Workbook

Sheet Cost Model
A1: Alpha Schools — West Palm Beach Public School Operator Model
A2: Sliding scale cost model | 3 campuses | Conservative buffers applied | For internal use — not for distribution
B3: Notes | D3: 800 Students | E3: 1,750 Students | F3: 2,500 Students | G3: 5,000 Students
D4: 800 | E4: 1750 | F4: 2500 | G4: 5000
A5: BUCKET 1 — ONE-TIME / UPFRONT COSTS
A7: Cost Item
A8: Deployment team — initial Alpha guides (3 months per campus) | B8: 3 campuses × $100K | D8: =Assumptions!$B$3*Assumptions!$B$13 -> 300000 | E8: =Assumptions!$B$3*Assumptions!$B$13 -> 300000 | F8: =Assumptions!$B$3*Assumptions!$B$13 -> 300000 | G8: =Assumptions!$B$3*Assumptions!$B$13 -> 300000
A9: Tech setup, SIS integration & device config | B9: $175K fixed + $150/student | D9: =Assumptions!$B$14+D$4*Assumptions!$B$15 -> 295000 | E9: =Assumptions!$B$14+E$4*Assumptions!$B$15 -> 437500 | F9: =Assumptions!$B$14+F$4*Assumptions!$B$15 -> 550000 | G9: =Assumptions!$B$14+G$4*Assumptions!$B$15 -> 925000
A10: Staff training & curriculum onboarding | B10: $2,500 × (students÷25) guides trained | D10: =CEILING(D$4/Assumptions!$B$4,1)*Assumptions!$B$16 -> 80000 | E10: =CEILING(E$4/Assumptions!$B$4,1)*Assumptions!$B$16 -> 175000 | F10: =CEILING(F$4/Assumptions!$B$4,1)*Assumptions!$B$16 -> 250000 | G10: =CEILING(G$4/Assumptions!$B$4,1)*Assumptions!$B$16 -> 500000
A11: ⚠ Device procurement (if district hardware insufficient) | B11: $500/student — conditional; verify district devices | D11: =D$4*Assumptions!$B$17 -> 400000 | E11: =E$4*Assumptions!$B$17 -> 875000 | F11: =F$4*Assumptions!$B$17 -> 1250000 | G11: =G$4*Assumptions!$B$17 -> 2500000
A12: Subtotal (excl. device procurement) | D12: =SUM(D8:D10) -> 675000 | E12: =SUM(E8:E10) -> 912500 | F12: =SUM(F8:F10) -> 1100000 | G12: =SUM(G8:G10) -> 1725000
A13: Overhead & contingency buffer (20%) | B13: Conservative add-on | D13: =D12*Assumptions!$B$18 -> 135000 | E13: =E12*Assumptions!$B$18 -> 182500 | F13: =F12*Assumptions!$B$18 -> 220000 | G13: =G12*Assumptions!$B$18 -> 345000
A14: TOTAL ONE-TIME COSTS (excl. devices) | D14: =D12+D13 -> 810000 | E14: =E12+E13 -> 1095000 | F14: =F12+F13 -> 1320000 | G14: =G12+G13 -> 2070000
A15: Per-student one-time cost | B15: One-time spend per enrolled student | D15: =D14/D$4 -> 1012.5 | E15: =E14/E$4 -> 625.71429 | F15: =F14/F$4 -> 528 | G15: =G14/G$4 -> 414
A17: BUCKET 2 — ONGOING ANNUAL COSTS (per school year)
A19: YEAR 1 — Full Alpha Carry
A20: Number of Alpha guides deployed | B20: ceil(students ÷ 25) | D20: =CEILING(D$4/Assumptions!$B$4,1) -> 32 | E20: =CEILING(E$4/Assumptions!$B$4,1) -> 70 | F20: =CEILING(F$4/Assumptions!$B$4,1) -> 100 | G20: =CEILING(G$4/Assumptions!$B$4,1) -> 200
A21: Campus Directors (3 campuses × $260K all-in) | B21: 3 CDs fixed regardless of enrollment | D21: =Assumptions!$B$3*Assumptions!$B$5 -> 780000 | E21: =Assumptions!$B$3*Assumptions!$B$5 -> 780000 | F21: =Assumptions!$B$3*Assumptions!$B$5 -> 780000 | G21: =Assumptions!$B$3*Assumptions!$B$5 -> 780000
A22: Alpha Guides (1:25 ratio × $130K all-in) | D22: =D20*Assumptions!$B$6 -> 4160000 | E22: =E20*Assumptions!$B$6 -> 9100000 | F22: =F20*Assumptions!$B$6 -> 13000000 | G22: =G20*Assumptions!$B$6 -> 26000000
A23: Staffing subtotal | D23: =D21+D22 -> 4940000 | E23: =E21+E22 -> 9880000 | F23: =F21+F22 -> 13780000 | G23: =G21+G22 -> 26780000
A24: Staffing buffer (15%) | B24: Benefits, attrition, contingency | D24: =D23*Assumptions!$B$8 -> 741000 | E24: =E23*Assumptions!$B$8 -> 1482000 | F24: =F23*Assumptions!$B$8 -> 2067000 | G24: =G23*Assumptions!$B$8 -> 4017000
A25: Timeback license ($5,000/student/yr) | D25: =D$4*Assumptions!$B$10 -> 4000000 | E25: =E$4*Assumptions!$B$10 -> 8750000 | F25: =F$4*Assumptions!$B$10 -> 12500000 | G25: =G$4*Assumptions!$B$10 -> 25000000
A26: Motivation budget ($800/student/yr — Access Model rate) | D26: =D$4*Assumptions!$B$11 -> 640000 | E26: =E$4*Assumptions!$B$11 -> 1400000 | F26: =F$4*Assumptions!$B$11 -> 2000000 | G26: =G$4*Assumptions!$B$11 -> 4000000
A27: TOTAL YEAR 1 ONGOING (annual) | D27: =D23+D24+D25+D26 -> 10321000 | E27: =E23+E24+E25+E26 -> 21512000 | F27: =F23+F24+F25+F26 -> 30347000 | G27: =G23+G24+G25+G26 -> 59797000
A28: Per-student Year 1 | D28: =D27/D$4 -> 12901.25 | E28: =E27/E$4 -> 12292.571 | F28: =F27/F$4 -> 12138.8 | G28: =G27/G$4 -> 11959.4
A30: YEAR 2 — 50% Guide Transition to District Payroll
A31: Campus Directors (unchanged — Alpha retains) | D31: =Assumptions!$B$3*Assumptions!$B$5 -> 780000 | E31: =Assumptions!$B$3*Assumptions!$B$5 -> 780000 | F31: =Assumptions!$B$3*Assumptions!$B$5 -> 780000 | G31: =Assumptions!$B$3*Assumptions!$B$5 -> 780000
A32: Alpha Guides (50% remaining — district absorbs other 50%) | D32: =CEILING(D$4/Assumptions!$B$4,1)*0.5*Assumptions!$B$6 -> 2080000 | E32: =CEILING(E$4/Assumptions!$B$4,1)*0.5*Assumptions!$B$6 -> 4550000 | F32: =CEILING(F$4/Assumptions!$B$4,1)*0.5*Assumptions!$B$6 -> 6500000 | G32: =CEILING(G$4/Assumptions!$B$4,1)*0.5*Assumptions!$B$6 -> 13000000
A33: Staffing subtotal | D33: =D31+D32 -> 2860000 | E33: =E31+E32 -> 5330000 | F33: =F31+F32 -> 7280000 | G33: =G31+G32 -> 13780000
A34: Staffing buffer (15%) | D34: =D33*Assumptions!$B$8 -> 429000 | E34: =E33*Assumptions!$B$8 -> 799500 | F34: =F33*Assumptions!$B$8 -> 1092000 | G34: =G33*Assumptions!$B$8 -> 2067000
A35: Timeback license | D35: =D$4*Assumptions!$B$10 -> 4000000 | E35: =E$4*Assumptions!$B$10 -> 8750000 | F35: =F$4*Assumptions!$B$10 -> 12500000 | G35: =G$4*Assumptions!$B$10 -> 25000000
A36: Motivation budget | D36: =D$4*Assumptions!$B$11 -> 640000 | E36: =E$4*Assumptions!$B$11 -> 1400000 | F36: =F$4*Assumptions!$B$11 -> 2000000 | G36: =G$4*Assumptions!$B$11 -> 4000000
A37: TOTAL YEAR 2 ONGOING (annual) | D37: =D33+D34+D35+D36 -> 7929000 | E37: =E33+E34+E35+E36 -> 16279500 | F37: =F33+F34+F35+F36 -> 22872000 | G37: =G33+G34+G35+G36 -> 44847000
A38: Per-student Year 2 | D38: =D37/D$4 -> 9911.25 | E38: =E37/E$4 -> 9302.5714 | F38: =F37/F$4 -> 9148.8 | G38: =G37/G$4 -> 8969.4
A40: YEAR 3 — District Carries Teaching Staff | Alpha: CDs + Coordinators + Platform
A41: Campus Directors (3 × $260K — Alpha retains) | D41: =Assumptions!$B$3*Assumptions!$B$5 -> 780000 | E41: =Assumptions!$B$3*Assumptions!$B$5 -> 780000 | F41: =Assumptions!$B$3*Assumptions!$B$5 -> 780000 | G41: =Assumptions!$B$3*Assumptions!$B$5 -> 780000
A42: Campus Coordinators (3 × $150K — 1 per campus, Y3+) | B42: Manages district-converted staff; Alpha's ongoing oversight layer | D42: =Assumptions!$B$3*Assumptions!$B$7 -> 450000 | E42: =Assumptions!$B$3*Assumptions!$B$7 -> 450000 | F42: =Assumptions!$B$3*Assumptions!$B$7 -> 450000 | G42: =Assumptions!$B$3*Assumptions!$B$7 -> 450000
A43: Staffing subtotal | D43: =D41+D42 -> 1230000 | E43: =E41+E42 -> 1230000 | F43: =F41+F42 -> 1230000 | G43: =G41+G42 -> 1230000
A44: Staffing buffer (15%) | D44: =D43*Assumptions!$B$8 -> 184500 | E44: =E43*Assumptions!$B$8 -> 184500 | F44: =F43*Assumptions!$B$8 -> 184500 | G44: =G43*Assumptions!$B$8 -> 184500
A45: Timeback license | D45: =D$4*Assumptions!$B$10 -> 4000000 | E45: =E$4*Assumptions!$B$10 -> 8750000 | F45: =F$4*Assumptions!$B$10 -> 12500000 | G45: =G$4*Assumptions!$B$10 -> 25000000
...

Sheet Assumptions
A1: Description | B1: Value | C1: Units | D1: Notes / Source
A2: STAFFING
A3: Number of campuses | B3: 3 | C3: campuses | D3: WPB: 2 elementary + 1 middle school
A4: Guide-to-student ratio | B4: 25 | C4: students/guide | D4: 1:25 per Alpha Access Model standard
A5: Campus Director — all-in cost | B5: 260000 | C5: $/yr | D5: Source: WPB Ops Blueprint (HISD mirror) — $200K base → $260K all-in
A6: Guide — all-in cost | B6: 130000 | C6: $/yr | D6: Source: WPB Ops Blueprint — $100K base → $130K all-in
A7: Campus Coordinator — all-in | B7: 150000 | C7: $/yr | D7: Y3+ only — supervises district-converted teachers on Alpha's behalf
A8: Staffing conservative buffer | B8: 0.15 | C8: 15% | D8: Add-on to all staffing costs for benefits, attrition, contingency
A9: PLATFORM & PROGRAMS
A10: Timeback license (per student/yr) | B10: 5000 | C10: $/student/yr | D10: Flat rate; volume discount TBD — not reflected here. Source: WPB Ops Blueprint
A11: Motivation budget (per student/yr) | B11: 800 | C11: $/student/yr | D11: Access Model confirmed rate (May 20 call). vs. $3,500–$13,500 for private Alpha
A12: ONE-TIME / UPFRONT COSTS
A13: Deployment team per campus (3-mo Alpha staff) | B13: 100000 | C13: $/campus | D13: Alpha guides deployed to train existing district teachers. ~3-month engagement per campus
A14: Tech setup & SIS integration (fixed) | B14: 175000 | C14: $ fixed | D14: One-time: SIS sync, device config, IT admin, platform onboarding. Independent of enrollment
A15: Tech setup per student (variable) | B15: 150 | C15: $/student | D15: Device configuration, account provisioning, testing
A16: Training & onboarding per guide-equivalent | B16: 2500 | C16: $/guide trained | D16: Curriculum training, Timeback certification, onboarding workshop per staff member retrained
A17: Device procurement — per student (conditional) | B17: 500 | C17: $/student | D17: ⚠️ Only if district hardware insufficient. Verify before including in final proposal
A18: One-time overhead & contingency buffer | B18: 0.2 | C18: 20% | D18: Conservative buffer on all one-time costs. Recommend keeping in proposal
A19: STAFFING RAMP SCHEDULE
A20: Year 1 — Alpha guide coverage | B20: 1 | C20: 100% | D20: Alpha carries all guides across all 3 campuses; coaches district staff up
A21: Year 2 — District absorbs guides | B21: 0.5 | C21: 50% | D21: 50% of Alpha guides convert to district payroll per campus
A22: Year 3 — District carries teachers | B22: 0 | C22: 0% | D22: All teaching staff on district payroll. Alpha retains CDs + Campus Coordinators
